# file: C:\Users\Couch\AppData\Roaming\Python\Python313\site-packages\celery\exceptions.py
# hypothesis_version: 6.141.1

[' state:', ' task_id:', 'AlreadyRegistered', 'AlwaysEagerIgnored', 'BackendError', 'BackendGetMetaError', 'BackendStoreError', 'CDeprecationWarning', 'CeleryError', 'CeleryWarning', 'ChordError', 'FixupWarning', 'Ignore', 'ImproperlyConfigured', 'IncompleteStream', 'InvalidTaskError', 'NotConfigured', 'NotRegistered', 'OperationalError', 'QueueNotFound', 'Reject', 'Retry', 'SecurityError', 'SecurityWarning', 'TaskError', 'TaskPredicate', 'TaskRevokedError', 'Terminated', 'TimeLimitExceeded', 'TimeoutError', 'WorkerLostError', 'WorkerShutdown', 'WorkerTerminate', 'reraise', 'state', 'task_args', 'task_id', 'task_kwargs']